{
  "status": {
    "test_error": "[Errno 32] Broken pipe"
  },
  "examples": [],
  "metadata": {
    "error": "[Errno 32] Broken pipe",
    "traceback": "Traceback (most recent call last):\n  File \"/home/barberb/ipfs_accelerate_py/test/skills/test_hf_bert.py\", line 1094, in test\n    output = test_handler(self.test_text)\n             ^^^^^^^^^^^^^^^^^^^^^^^^^^^^\n  File \"/home/barberb/ipfs_accelerate_py/ipfs_accelerate_py/worker/skillset/hf_bert.py\", line 1413, in handler\n    raise e\n  File \"/home/barberb/ipfs_accelerate_py/ipfs_accelerate_py/worker/skillset/hf_bert.py\", line 1400, in handler\n    last_hidden = hidden_states.masked_fill(~attention_mask.bool().unsqueeze(-1), 0.0)\n                  ^^^^^^^^^^^^^^^^^^^^^^^^^^^^^^^^^^^^^^^^^^^^^^^^^^^^^^^^^^^^^^^^^^^^\nRuntimeError: The size of tensor a (11) must match the size of tensor b (10) at non-singleton dimension 1\n\nDuring handling of the above exception, another exception occurred:\n\nTraceback (most recent call last):\n  File \"/home/barberb/ipfs_accelerate_py/test/skills/test_hf_bert.py\", line 1146, in __test__\n    test_results = self.test()\n                   ^^^^^^^^^^^\n  File \"/home/barberb/ipfs_accelerate_py/test/skills/test_hf_bert.py\", line 1116, in test\n    traceback.print_exc()\n  File \"/usr/lib/python3.12/traceback.py\", line 180, in print_exc\n    print_exception(sys.exception(), limit=limit, file=file, chain=chain)\n  File \"/usr/lib/python3.12/traceback.py\", line 125, in print_exception\n    te.print(file=file, chain=chain)\n  File \"/usr/lib/python3.12/traceback.py\", line 1050, in print\n    print(line, file=file, end=\"\")\nBrokenPipeError: [Errno 32] Broken pipe\n"
  }
}