{
  "timestamp": "2025-02-28T00:41:45.934097",
  "python_version": "3.12.3 (main, Feb  4 2025, 14:48:35) [GCC 13.3.0]",
  "command": "run_performance_tests.py --skills --filter hf_clip",
  "skill_tests": {
    "test_hf_clip.py": {
      "test_file": "test_hf_clip.py",
      "elapsed_time": 24.96023440361023,
      "return_code": 0,
      "stdout": "connecting to master\nconnecting to master\nInitializing CLIP for CPU...\nCLIP initialization status: {'torch': True, 'transformers': True, 'numpy': True}\nLoading openai/clip-vit-base-patch16 for CPU inference...\nCreating minimal CLIP model for testing\nTesting CLIP text-to-image similarity...\nTesting CLIP image embedding...\nTesting CLIP text embedding...\nTesting CLIP on CUDA...\nSuccessfully imported CUDA utilities via path insertion\nAttempting to initialize real CUDA implementation...\nCLIP initialization status: {'torch': True, 'transformers': True, 'numpy': True}\nInitializing CLIP model openai/clip-vit-base-patch16 for CUDA inference...\nUsing CUDA device: Quadro P4000 (index 0)\nError loading model configuration: openai/clip-vit-base-patch16 is not a local folder and is not a valid model identifier listed on 'https://huggingface.co/models'\nIf this is a private repository, make sure to pass a token having permission to this repo either by logging in with `huggingface-cli login` or by passi...",
      "stderr": "The argument `trust_remote_code` is to be used with Auto classes. It has no effect here and is ignored.\n2025-02-28 00:41:55,706 - datasets - INFO - PyTorch version 2.4.0 available.\nCould not infer whether the model was already converted or not to the OpenVINO IR, keeping `export=True`.\n401 Client Error. (Request ID: Root=1-67c176d4-5dc3216b2387a39d3e7283ac;11a65059-09ff-4617-84d6-d85abbefec06)\n\nRepository Not Found for url: https://huggingface.co/api/models/openai/clip-vit-base-patch16/tree/main?recursive=True&expand=False.\nPlease make sure you specified the correct `repo_id` and `repo_type`.\nIf you are trying to access a private or gated repo, make sure you are authenticated.\nInvalid credentials in Authorization header\nTraceback (most recent call last):\n  File \"/home/barberb/.local/lib/python3.12/site-packages/huggingface_hub/utils/_http.py\", line 406, in hf_raise_for_status\n    response.raise_for_status()\n  File \"/usr/lib/python3/dist-packages/requests/models.py\", line 1021, in raise...",
      "json_parse_error": "Expecting property name enclosed in double quotes: line 1 column 2 (char 1)"
    }
  }
}